File: specimen.csv
Time(s) ,Extension(mm),Load(kN),Flexural stress(MPa),Flexural strain(%)
,,,,
0,0,0,0,0
0.2,0,0,-0.01,0
0.4,0.01,0,0.07,0
0.6,0.01,0,0.1,0
0.8,0.01,0,0.18,0.01
1,0.02,0,0.22,0.01
1.2,0.02,0,0.3,0.01
1.4,0.02,0,0.34,0.01
1.6,0.03,0,0.35,0.01
1.8,0.03,0,0.39,0.02
2,0.03,0,0.44,0.02
2.2,0.04,0,0.49,0.02
2.4,0.04,0,0.53,0.02
2.6,0.04,0,0.58,0.02
2.8,0.05,0,0.64,0.03
3,0.05,0,0.65,0.03
3.2,0.05,0,0.65,0.03
3.4,0.06,0,0.69,0.03
3.6,0.06,0,0.75,0.03
3.8,0.06,0,0.81,0.04
4,0.07,0,0.83,0.04
4.2,0.07,0,0.88,0.04
4.4,0.07,0,0.88,0.04
4.6,0.08,0,0.97,0.04
4.8,0.08,0,0.94,0.05
5,0.08,0,1.03,0.05
5.2,0.09,0,1.01,0.05
5.4,0.09,0,1.04,0.05
5.6,0.09,0,1.04,0.05
5.8,0.1,0,1.14,0.06
6,0.1,0,1.15,0.06
6.2,0.1,0,1.18,0.06
6.4,0.11,0,1.23,0.06
6.6,0.11,0,1.2,0.06
6.8,0.11,0,1.26,0.07
7,0.12,0,1.34,0.07
7.2,0.12,0,1.4,0.07
7.4,0.12,0,1.37,0.07
7.6,0.13,0,1.36,0.07
7.8,0.13,0,1.45,0.07
8,0.13,0,1.46,0.08
8.2,0.14,0,1.51,0.08
8.4,0.14,0,1.5,0.08
8.6,0.14,0,1.54,0.08
8.8,0.15,0,1.62,0.08
9,0.15,0,1.65,0.09
9.2,0.15,0,1.67,0.09
9.4,0.16,0,1.72,0.09
9.6,0.16,0,1.72,0.09
9.8,0.16,0,1.78,0.09
10,0.17,0,1.8,0.1
10.2,0.17,0,1.78,0.1
10.4,0.17,0,1.85,0.1
10.6,0.18,0,1.89,0.1
10.8,0.18,0,1.95,0.1
11,0.18,0,1.9,0.11
11.2,0.19,0,1.98,0.11
11.4,0.19,0,2.02,0.11
11.6,0.19,0,2.02,0.11
11.8,0.2,0,2.06,0.11
12,0.2,0,2.15,0.12
12.2,0.2,0,2.11,0.12
12.4,0.21,0,2.15,0.12
12.6,0.21,0,2.22,0.12
12.8,0.21,0,2.22,0.12
13,0.22,0,2.28,0.13
13.2,0.22,0,2.32,0.13
13.4,0.22,0,2.32,0.13
13.6,0.23,0,2.38,0.13
13.8,0.23,0,2.37,0.13
14,0.23,0,2.43,0.14
14.2,0.24,0,2.38,0.14
14.4,0.24,0,2.45,0.14
14.6,0.24,0.01,2.52,0.14
14.8,0.25,0.01,2.58,0.14
15,0.25,0.01,2.63,0.15
15.2,0.25,0.01,2.62,0.15
15.4,0.26,0.01,2.7,0.15
15.6,0.26,0.01,2.71,0.15
15.8,0.26,0.01,2.79,0.15
16,0.27,0.01,2.82,0.15
16.2,0.27,0.01,2.87,0.16
16.4,0.27,0.01,2.94,0.16
16.6,0.28,0.01,2.98,0.16
16.8,0.28,0.01,3.06,0.16
17,0.28,0.01,3.05,0.16
17.2,0.29,0.01,3.19,0.17
17.4,0.29,0.01,3.22,0.17
17.6,0.29,0.01,3.29,0.17
17.8,0.3,0.01,3.38,0.17
18,0.3,0.01,3.41,0.17
18.2,0.3,0.01,3.51,0.18
18.4,0.31,0.01,3.63,0.18
18.6,0.31,0.01,3.69,0.18
18.8,0.31,0.01,3.78,0.18
19,0.32,0.01,3.88,0.18
19.2,0.32,0.01,3.96,0.19
19.4,0.32,0.01,4.05,0.19
19.6,0.33,0.01,4.16,0.19
19.8,0.33,0.01,4.14,0.19
20,0.33,0.01,4.31,0.19
20.2,0.34,0.01,4.35,0.2
20.4,0.34,0.01,4.43,0.2
20.6,0.34,0.01,4.5,0.2
20.8,0.35,0.01,4.64,0.2
21,0.35,0.01,4.7,0.2
21.2,0.35,0.01,4.77,0.21
21.4,0.36,0.01,4.84,0.21
21.6,0.36,0.01,4.87,0.21
21.8,0.36,0.01,4.87,0.21
22,0.37,0.01,5.06,0.21
22.2,0.37,0.01,5.09,0.22
22.4,0.37,0.01,5.24,0.22
22.6,0.38,0.01,5.26,0.22
22.8,0.38,0.01,5.29,0.22
23,0.38,0.01,5.41,0.22
23.2,0.39,0.01,5.46,0.22
23.4,0.39,0.01,5.5,0.23
23.6,0.39,0.01,5.54,0.23
23.8,0.4,0.01,5.64,0.23
24,0.4,0.01,5.64,0.23
24.2,0.4,0.01,5.65,0.23
24.4,0.41,0.01,5.74,0.24
24.6,0.41,0.01,5.8,0.24
24.8,0.41,0.01,5.82,0.24
25,0.42,0.01,5.89,0.24
25.2,0.42,0.01,5.92,0.24
25.4,0.42,0.01,5.95,0.25
25.6,0.43,0.01,5.94,0.25
25.8,0.43,0.01,6.1,0.25
26,0.43,0.01,6.13,0.25
26.2,0.44,0.01,6.1,0.25
26.4,0.44,0.01,6.23,0.26
26.6,0.44,0.01,6.25,0.26
26.8,0.45,0.01,6.31,0.26
27,0.45,0.01,6.33,0.26
27.2,0.45,0.01,6.38,0.26
27.4,0.46,0.01,6.44,0.27
27.6,0.46,0.01,6.47,0.27
27.8,0.46,0.01,6.56,0.27
28,0.47,0.01,6.65,0.27
28.2,0.47,0.01,6.7,0.27
28.4,0.47,0.01,6.7,0.28
28.6,0.48,0.01,6.86,0.28
28.8,0.48,0.01,6.86,0.28
29,0.48,0.01,6.92,0.28
29.2,0.49,0.01,7,0.28
29.4,0.49,0.01,7.04,0.29
29.6,0.49,0.01,7.05,0.29
29.8,0.5,0.01,7.15,0.29
30,0.5,0.01,7.17,0.29
30.2,0.5,0.01,7.25,0.29
30.4,0.51,0.01,7.27,0.29
30.6,0.51,0.01,7.34,0.3
30.8,0.51,0.02,7.39,0.3
31,0.52,0.02,7.42,0.3
31.2,0.52,0.02,7.44,0.3
31.4,0.52,0.02,7.46,0.3
31.6,0.53,0.02,7.49,0.31
31.8,0.53,0.02,7.54,0.31
32,0.53,0.02,7.58,0.31
32.2,0.54,0.02,7.56,0.31
32.4,0.54,0.02,7.69,0.31
32.6,0.54,0.02,7.63,0.32
32.8,0.55,0.02,7.67,0.32
33,0.55,0.02,7.68,0.32
33.2,0.55,0.02,7.82,0.32
33.4,0.56,0.02,7.73,0.32
33.6,0.56,0.02,7.92,0.33
33.8,0.56,0.02,7.91,0.33
34,0.57,0.02,7.99,0.33
34.2,0.57,0.02,8.02,0.33
34.4,0.57,0.02,8.08,0.33
34.6,0.58,0.02,8.19,0.34
34.8,0.58,0.02,8.19,0.34
35,0.58,0.02,8.22,0.34
35.2,0.59,0.02,8.29,0.34
35.4,0.59,0.02,8.36,0.34
35.6,0.59,0.02,8.44,0.35
35.8,0.6,0.02,8.47,0.35
36,0.6,0.02,8.53,0.35
36.2,0.6,0.02,8.61,0.35
36.4,0.61,0.02,8.6,0.35
36.6,0.61,0.02,8.68,0.35
36.8,0.61,0.02,8.73,0.36
37,0.62,0.02,8.78,0.36
37.2,0.62,0.02,8.82,0.36
37.4,0.62,0.02,8.87,0.36
37.6,0.63,0.02,8.94,0.36
37.8,0.63,0.02,8.98,0.37
38,0.63,0.02,9.07,0.37
38.2,0.64,0.02,9.16,0.37
38.4,0.64,0.02,9.17,0.37
38.6,0.64,0.02,9.22,0.37
38.8,0.65,0.02,9.28,0.38
39,0.65,0.02,9.37,0.38
39.2,0.65,0.02,9.42,0.38
39.4,0.66,0.02,9.42,0.38
39.6,0.66,0.02,9.56,0.38
39.8,0.66,0.02,9.57,0.39
40,0.67,0.02,9.75,0.39
40.2,0.67,0.02,9.73,0.39
40.4,0.67,0.02,9.81,0.39
40.6,0.68,0.02,9.84,0.39
40.8,0.68,0.02,9.91,0.4
41,0.68,0.02,9.95,0.4
41.2,0.69,0.02,10.08,0.4
41.4,0.69,0.02,10.09,0.4
41.6,0.69,0.02,10.17,0.4
41.8,0.7,0.02,10.27,0.41
42,0.7,0.02,10.32,0.41
42.2,0.7,0.02,10.37,0.41
42.4,0.71,0.02,10.45,0.41
42.6,0.71,0.02,10.47,0.41
42.8,0.71,0.02,10.55,0.42
43,0.72,0.02,10.58,0.42
43.2,0.72,0.02,10.71,0.42
43.4,0.72,0.02,10.76,0.42
43.6,0.73,0.02,10.86,0.42
43.8,0.73,0.02,10.86,0.42
44,0.73,0.02,10.94,0.43
44.2,0.74,0.02,11.03,0.43
44.4,0.74,0.02,11.1,0.43
44.6,0.74,0.02,11.17,0.43
44.8,0.75,0.02,11.25,0.43
45,0.75,0.02,11.28,0.44
45.2,0.75,0.02,11.36,0.44
45.4,0.75,0.02,11.4,0.44
45.6,0.76,0.02,11.44,0.44
45.8,0.76,0.02,11.48,0.44
46,0.77,0.02,11.58,0.45
46.2,0.77,0.02,11.65,0.45
46.4,0.77,0.02,11.69,0.45
46.6,0.78,0.02,11.79,0.45
46.8,0.78,0.02,11.84,0.45
47,0.78,0.02,11.93,0.46
47.2,0.79,0.02,11.97,0.46
47.4,0.79,0.02,12,0.46
47.6,0.79,0.02,12.09,0.46
47.8,0.8,0.02,12.15,0.46
48,0.8,0.02,12.23,0.47
48.2,0.8,0.03,12.29,0.47
48.4,0.81,0.03,12.34,0.47
48.6,0.81,0.03,12.41,0.47
48.8,0.81,0.03,12.52,0.47
49,0.82,0.03,12.57,0.48
49.2,0.82,0.03,12.62,0.48
49.4,0.82,0.03,12.66,0.48
49.6,0.83,0.03,12.74,0.48
49.8,0.83,0.03,12.85,0.48
50,0.83,0.03,12.86,0.49
50.2,0.83,0.03,12.93,0.49
50.4,0.84,0.03,13.02,0.49
50.6,0.84,0.03,13.08,0.49
50.8,0.85,0.03,13.13,0.49
51,0.85,0.03,13.19,0.49
51.2,0.85,0.03,13.26,0.5
51.4,0.86,0.03,13.35,0.5
51.6,0.86,0.03,13.34,0.5
51.8,0.86,0.03,13.47,0.5
52,0.87,0.03,13.56,0.5
52.2,0.87,0.03,13.54,0.51
52.4,0.87,0.03,13.63,0.51
52.6,0.88,0.03,13.71,0.51
52.8,0.88,0.03,13.82,0.51
53,0.88,0.03,13.83,0.51
53.2,0.89,0.03,13.93,0.52
53.4,0.89,0.03,13.98,0.52
53.6,0.89,0.03,14.02,0.52
53.8,0.9,0.03,14.05,0.52
54,0.9,0.03,14.15,0.52
54.2,0.9,0.03,14.22,0.53
54.4,0.91,0.03,14.3,0.53
54.6,0.91,0.03,14.34,0.53
54.8,0.91,0.03,14.4,0.53
55,0.92,0.03,14.49,0.53
55.2,0.92,0.03,14.56,0.54
55.4,0.92,0.03,14.6,0.54
55.6,0.93,0.03,14.74,0.54
55.8,0.93,0.03,14.74,0.54
56,0.93,0.03,14.85,0.54
56.2,0.94,0.03,14.82,0.55
56.4,0.94,0.03,14.98,0.55
56.6,0.94,0.03,15.03,0.55
56.8,0.95,0.03,15.09,0.55
57,0.95,0.03,15.12,0.55
57.2,0.95,0.03,15.21,0.56
57.4,0.96,0.03,15.22,0.56
57.6,0.96,0.03,15.32,0.56
57.8,0.96,0.03,15.38,0.56
58,0.97,0.03,15.48,0.56
58.2,0.97,0.03,15.53,0.57
58.4,0.97,0.03,15.63,0.57
58.6,0.98,0.03,15.67,0.57
58.8,0.98,0.03,15.71,0.57
59,0.98,0.03,15.74,0.57
59.2,0.99,0.03,15.85,0.57
59.4,0.99,0.03,15.95,0.58
59.6,0.99,0.03,15.93,0.58
59.8,1,0.03,16.06,0.58
60,1,0.03,16.11,0.58
60.2,1,0.03,16.17,0.58
60.4,1.01,0.03,16.24,0.59
60.6,1.01,0.03,16.32,0.59
60.8,1.01,0.03,16.41,0.59
61,1.02,0.03,16.42,0.59
61.2,1.02,0.03,16.48,0.59
61.4,1.02,0.03,16.56,0.6
61.6,1.03,0.03,16.65,0.6
61.8,1.03,0.03,16.73,0.6
62,1.03,0.03,16.74,0.6
62.2,1.04,0.03,16.86,0.6
62.4,1.04,0.03,16.93,0.61
62.6,1.04,0.03,16.98,0.61
62.8,1.05,0.03,17.02,0.61
63,1.05,0.03,17.11,0.61
63.2,1.05,0.03,17.12,0.61
63.4,1.06,0.04,17.19,0.62
63.6,1.06,0.04,17.28,0.62
63.8,1.06,0.04,17.38,0.62
64,1.07,0.04,17.35,0.62
64.2,1.07,0.04,17.48,0.62
64.4,1.07,0.04,17.55,0.63
64.6,1.08,0.04,17.6,0.63
64.8,1.08,0.04,17.74,0.63
65,1.08,0.04,17.76,0.63
65.2,1.09,0.04,17.8,0.63
65.4,1.09,0.04,17.9,0.63
65.6,1.09,0.04,17.97,0.64
65.8,1.1,0.04,18.03,0.64
66,1.1,0.04,18.05,0.64
66.2,1.1,0.04,18.16,0.64
66.4,1.11,0.04,18.25,0.64
66.6,1.11,0.04,18.29,0.65
66.8,1.11,0.04,18.28,0.65
67,1.12,0.04,18.38,0.65
67.2,1.12,0.04,18.44,0.65
67.4,1.12,0.04,18.48,0.65
67.6,1.13,0.04,18.58,0.66
67.8,1.13,0.04,18.69,0.66
68,1.13,0.04,18.73,0.66
68.2,1.14,0.04,18.8,0.66
68.4,1.14,0.04,18.87,0.66
68.6,1.14,0.04,18.97,0.67
68.8,1.15,0.04,19.03,0.67
69,1.15,0.04,19.04,0.67
69.2,1.15,0.04,19.13,0.67
69.4,1.16,0.04,19.21,0.67
69.6,1.16,0.04,19.28,0.68
69.8,1.16,0.04,19.31,0.68
70,1.17,0.04,19.41,0.68
70.2,1.17,0.04,19.41,0.68
70.4,1.17,0.04,19.5,0.68
70.6,1.18,0.04,19.64,0.69
70.8,1.18,0.04,19.68,0.69
71,1.18,0.04,19.67,0.69
71.2,1.19,0.04,19.75,0.69
71.4,1.19,0.04,19.85,0.69
71.6,1.19,0.04,19.88,0.7
71.8,1.2,0.04,19.98,0.7
72,1.2,0.04,20.03,0.7
72.2,1.2,0.04,20.06,0.7
72.4,1.21,0.04,20.21,0.7
72.6,1.21,0.04,20.24,0.7
72.8,1.21,0.04,20.32,0.71
73,1.22,0.04,20.34,0.71
73.2,1.22,0.04,20.4,0.71
73.4,1.22,0.04,20.49,0.71
73.6,1.23,0.04,20.6,0.71
73.8,1.23,0.04,20.66,0.72
74,1.23,0.04,20.65,0.72
74.2,1.24,0.04,20.72,0.72
74.4,1.24,0.04,20.79,0.72
74.6,1.24,0.04,20.91,0.72
74.8,1.25,0.04,20.95,0.73
75,1.25,0.04,21.06,0.73
75.2,1.25,0.04,21.13,0.73
75.4,1.26,0.04,21.13,0.73
75.6,1.26,0.04,21.2,0.73
75.8,1.26,0.04,21.26,0.74
76,1.27,0.04,21.36,0.74
76.2,1.27,0.04,21.4,0.74
76.4,1.27,0.04,21.42,0.74
76.6,1.28,0.04,21.55,0.74
76.8,1.28,0.04,21.61,0.75
77,1.28,0.04,21.67,0.75
77.2,1.29,0.04,21.72,0.75
77.4,1.29,0.04,21.79,0.75
77.6,1.29,0.04,21.88,0.75
77.8,1.3,0.04,21.88,0.76
78,1.3,0.04,21.99,0.76
78.2,1.3,0.04,22.04,0.76
78.4,1.31,0.05,22.04,0.76
78.6,1.31,0.05,22.17,0.76
78.8,1.31,0.05,22.19,0.77
79,1.32,0.05,22.33,0.77
79.2,1.32,0.05,22.35,0.77
79.4,1.32,0.05,22.48,0.77
79.6,1.33,0.05,22.48,0.77
79.8,1.33,0.05,22.56,0.77
80,1.33,0.05,22.64,0.78
80.2,1.34,0.05,22.71,0.78
80.4,1.34,0.05,22.79,0.78
80.6,1.34,0.05,22.74,0.78
80.8,1.35,0.05,22.9,0.78
81,1.35,0.05,22.95,0.79
81.2,1.35,0.05,23.01,0.79
81.4,1.36,0.05,23.08,0.79
81.6,1.36,0.05,23.15,0.79
81.8,1.36,0.05,23.21,0.79
82,1.37,0.05,23.31,0.8
82.2,1.37,0.05,23.33,0.8
82.4,1.37,0.05,23.41,0.8
82.6,1.38,0.05,23.45,0.8
82.8,1.38,0.05,23.56,0.8
83,1.38,0.05,23.55,0.81
83.2,1.39,0.05,23.68,0.81
83.4,1.39,0.05,23.8,0.81
83.6,1.39,0.05,23.82,0.81
83.8,1.4,0.05,23.89,0.81
84,1.4,0.05,23.9,0.82
84.2,1.4,0.05,23.97,0.82
84.4,1.41,0.05,24.01,0.82
84.6,1.41,0.05,24.07,0.82
84.8,1.41,0.05,24.13,0.82
85,1.42,0.05,24.26,0.83
85.2,1.42,0.05,24.26,0.83
85.4,1.42,0.05,24.38,0.83
85.6,1.43,0.05,24.4,0.83
85.8,1.43,0.05,24.51,0.83
86,1.43,0.05,24.59,0.84
86.2,1.44,0.05,24.65,0.84
86.4,1.44,0.05,24.7,0.84
86.6,1.44,0.05,24.74,0.84
86.8,1.45,0.05,24.85,0.84
87,1.45,0.05,24.93,0.84
87.2,1.45,0.05,24.98,0.85
87.4,1.46,0.05,25.05,0.85
87.6,1.46,0.05,25.07,0.85
87.8,1.46,0.05,25.16,0.85
88,1.47,0.05,25.26,0.85
88.2,1.47,0.05,25.25,0.86
88.4,1.47,0.05,25.36,0.86
88.6,1.48,0.05,25.48,0.86
88.8,1.48,0.05,25.48,0.86
89,1.48,0.05,25.58,0.86
89.2,1.49,0.05,25.61,0.87
89.4,1.49,0.05,25.69,0.87
89.6,1.49,0.05,25.76,0.87
89.8,1.5,0.05,25.84,0.87
90,1.5,0.05,25.92,0.87
90.2,1.5,0.05,25.95,0.88
90.4,1.51,0.05,26,0.88
90.6,1.51,0.05,26.08,0.88
90.8,1.51,0.05,26.11,0.88
91,1.52,0.05,26.21,0.88
91.2,1.52,0.05,26.29,0.89
91.4,1.52,0.05,26.33,0.89
91.6,1.53,0.05,26.4,0.89
91.8,1.53,0.05,26.5,0.89
92,1.53,0.05,26.54,0.89
92.2,1.54,0.05,26.61,0.9
92.4,1.54,0.05,26.69,0.9
92.6,1.54,0.05,26.78,0.9
92.8,1.55,0.05,26.82,0.9
93,1.55,0.05,26.85,0.9
93.2,1.55,0.06,26.94,0.91
93.4,1.56,0.06,27,0.91
93.6,1.56,0.06,27.07,0.91
93.8,1.56,0.06,27.15,0.91
94,1.57,0.06,27.2,0.91
94.2,1.57,0.06,27.25,0.92
94.4,1.57,0.06,27.26,0.92
94.6,1.58,0.06,27.43,0.92
94.8,1.58,0.06,27.5,0.92
95,1.58,0.06,27.5,0.92
95.2,1.59,0.06,27.64,0.92
95.4,1.59,0.06,27.65,0.93
95.6,1.59,0.06,27.69,0.93
95.8,1.6,0.06,27.76,0.93
96,1.6,0.06,27.84,0.93
96.2,1.6,0.06,27.94,0.93
96.4,1.61,0.06,27.98,0.94
96.6,1.61,0.06,28.08,0.94
96.8,1.61,0.06,28.13,0.94
97,1.62,0.06,28.18,0.94
97.2,1.62,0.06,28.21,0.94
97.4,1.62,0.06,28.28,0.95
97.6,1.63,0.06,28.41,0.95
97.8,1.63,0.06,28.44,0.95
98,1.63,0.06,28.49,0.95
98.2,1.64,0.06,28.58,0.95
98.4,1.64,0.06,28.67,0.96
98.6,1.64,0.06,28.68,0.96
98.8,1.65,0.06,28.78,0.96
99,1.65,0.06,28.85,0.96
99.2,1.65,0.06,28.9,0.96
99.4,1.66,0.06,28.94,0.97
99.6,1.66,0.06,29.07,0.97
99.8,1.66,0.06,29.08,0.97
100,1.67,0.06,29.22,0.97
100.2,1.67,0.06,29.19,0.97
100.4,1.67,0.06,29.31,0.98
100.6,1.68,0.06,29.35,0.98
100.8,1.68,0.06,29.42,0.98
101,1.68,0.06,29.52,0.98
101.2,1.69,0.06,29.52,0.98
101.4,1.69,0.06,29.68,0.99
101.6,1.69,0.06,29.72,0.99
101.8,1.7,0.06,29.79,0.99
102,1.7,0.06,29.84,0.99
102.2,1.7,0.06,29.89,0.99
102.4,1.71,0.06,29.98,0.99
102.6,1.71,0.06,29.97,1
102.8,1.71,0.06,30.08,1
103,1.72,0.06,30.11,1
103.2,1.72,0.06,30.22,1
103.4,1.72,0.06,30.27,1
103.6,1.73,0.06,30.33,1.01
103.8,1.73,0.06,30.4,1.01
104,1.73,0.06,30.46,1.01
104.2,1.74,0.06,30.48,1.01
104.4,1.74,0.06,30.64,1.01
104.6,1.74,0.06,30.67,1.02
104.8,1.75,0.06,30.72,1.02
105,1.75,0.06,30.81,1.02
105.2,1.75,0.06,30.92,1.02
105.4,1.76,0.06,30.94,1.02
105.6,1.76,0.06,31.05,1.03
105.8,1.76,0.06,31.07,1.03
106,1.77,0.06,31.17,1.03
106.2,1.77,0.06,31.21,1.03
106.4,1.77,0.06,31.3,1.03
106.6,1.78,0.06,31.35,1.04
106.8,1.78,0.06,31.34,1.04
107,1.78,0.06,31.47,1.04
107.2,1.79,0.06,31.53,1.04
107.4,1.79,0.06,31.6,1.04
107.6,1.79,0.06,31.68,1.05
107.8,1.8,0.06,31.71,1.05
108,1.8,0.06,31.81,1.05
108.2,1.8,0.07,31.87,1.05
108.4,1.81,0.07,31.91,1.05
108.6,1.81,0.07,31.95,1.06
108.8,1.81,0.07,32.04,1.06
109,1.82,0.07,32.12,1.06
109.2,1.82,0.07,32.22,1.06
109.4,1.82,0.07,32.25,1.06
109.6,1.83,0.07,32.33,1.06
109.8,1.83,0.07,32.4,1.07
110,1.83,0.07,32.5,1.07
110.2,1.84,0.07,32.55,1.07
110.4,1.84,0.07,32.58,1.07
110.6,1.84,0.07,32.6,1.07
110.8,1.84,0.07,32.69,1.08
111,1.85,0.07,32.76,1.08
111.2,1.85,0.07,32.81,1.08
111.4,1.86,0.07,32.93,1.08
111.6,1.86,0.07,32.96,1.08
111.8,1.86,0.07,33.03,1.09
112,1.87,0.07,33.1,1.09
112.2,1.87,0.07,33.14,1.09
112.4,1.87,0.07,33.27,1.09
112.6,1.88,0.07,33.36,1.09
112.8,1.88,0.07,33.36,1.1
113,1.88,0.07,33.48,1.1
113.2,1.89,0.07,33.58,1.1
113.4,1.89,0.07,33.55,1.1
113.6,1.89,0.07,33.62,1.1
113.8,1.9,0.07,33.71,1.11
114,1.9,0.07,33.75,1.11
114.2,1.9,0.07,33.83,1.11
114.4,1.91,0.07,33.9,1.11
114.6,1.91,0.07,33.93,1.11
114.8,1.91,0.07,34.06,1.12
115,1.92,0.07,34.04,1.12
115.2,1.92,0.07,34.21,1.12
115.4,1.92,0.07,34.22,1.12
115.6,1.93,0.07,34.3,1.12
115.8,1.93,0.07,34.39,1.13
116,1.93,0.07,34.4,1.13
116.2,1.94,0.07,34.49,1.13
116.4,1.94,0.07,34.55,1.13
116.6,1.94,0.07,34.63,1.13
116.8,1.95,0.07,34.68,1.13
117,1.95,0.07,34.75,1.14
117.2,1.95,0.07,34.81,1.14
117.4,1.96,0.07,34.89,1.14
117.6,1.96,0.07,34.93,1.14
117.8,1.96,0.07,34.99,1.14
118,1.97,0.07,35.06,1.15
118.2,1.97,0.07,35.13,1.15
118.4,1.97,0.07,35.26,1.15
118.6,1.98,0.07,35.31,1.15
118.8,1.98,0.07,35.34,1.15
119,1.98,0.07,35.42,1.16
119.2,1.99,0.07,35.46,1.16
119.4,1.99,0.07,35.52,1.16
119.6,1.99,0.07,35.64,1.16
119.8,1.99,0.07,35.66,1.16
120,2,0.07,35.73,1.17
120.2,2,0.07,35.77,1.17
120.4,2.01,0.07,35.83,1.17
120.6,2.01,0.07,35.92,1.17
120.8,2.01,0.07,35.96,1.17
121,2.02,0.07,36.07,1.18
121.2,2.02,0.07,36.15,1.18
121.4,2.02,0.07,36.21,1.18
121.6,2.03,0.07,36.27,1.18
121.8,2.03,0.07,36.33,1.18
122,2.03,0.07,36.41,1.19
122.2,2.04,0.07,36.4,1.19
122.4,2.04,0.07,36.54,1.19
122.6,2.04,0.07,36.65,1.19
122.8,2.05,0.07,36.65,1.19
123,2.05,0.08,36.76,1.19
123.2,2.05,0.08,36.75,1.2
123.4,2.06,0.08,36.85,1.2
123.6,2.06,0.08,36.95,1.2
123.8,2.06,0.08,37.01,1.2
124,2.07,0.08,37.03,1.2
124.2,2.07,0.08,37.09,1.21
124.4,2.07,0.08,37.18,1.21
124.6,2.08,0.08,37.24,1.21
124.8,2.08,0.08,37.29,1.21
125,2.08,0.08,37.32,1.21
125.2,2.09,0.08,37.47,1.22
125.4,2.09,0.08,37.5,1.22
125.6,2.09,0.08,37.61,1.22
125.8,2.1,0.08,37.67,1.22
126,2.1,0.08,37.71,1.22
126.2,2.1,0.08,37.73,1.23
126.4,2.11,0.08,37.86,1.23
126.6,2.11,0.08,37.88,1.23
126.8,2.11,0.08,37.97,1.23
127,2.12,0.08,38.1,1.23
127.2,2.12,0.08,38.09,1.24
127.4,2.12,0.08,38.18,1.24
127.6,2.13,0.08,38.27,1.24
127.8,2.13,0.08,38.25,1.24
128,2.13,0.08,38.38,1.24
128.2,2.14,0.08,38.46,1.25
128.4,2.14,0.08,38.53,1.25
128.6,2.14,0.08,38.54,1.25
128.8,2.15,0.08,38.65,1.25
129,2.15,0.08,38.66,1.25
129.2,2.15,0.08,38.76,1.26
129.4,2.16,0.08,38.85,1.26
129.6,2.16,0.08,38.9,1.26
129.8,2.16,0.08,38.99,1.26
130,2.17,0.08,39.01,1.26
130.2,2.17,0.08,39.12,1.26
130.4,2.17,0.08,39.19,1.27
130.6,2.18,0.08,39.16,1.27
130.8,2.18,0.08,39.3,1.27
131,2.18,0.08,39.32,1.27
131.2,2.19,0.08,39.41,1.27
131.4,2.19,0.08,39.4,1.28
131.6,2.19,0.08,39.51,1.28
131.8,2.2,0.08,39.59,1.28
132,2.2,0.08,39.72,1.28
132.2,2.2,0.08,39.76,1.28
132.4,2.21,0.08,39.85,1.29
132.6,2.21,0.08,39.86,1.29
132.8,2.21,0.08,39.93,1.29
133,2.22,0.08,39.98,1.29
133.2,2.22,0.08,40.1,1.29
133.4,2.22,0.08,40.18,1.3
133.6,2.23,0.08,40.24,1.3
133.8,2.23,0.08,40.27,1.3
134,2.23,0.08,40.34,1.3
134.2,2.24,0.08,40.43,1.3
134.4,2.24,0.08,40.47,1.31
134.6,2.24,0.08,40.58,1.31
134.8,2.25,0.08,40.61,1.31
135,2.25,0.08,40.66,1.31
135.2,2.25,0.08,40.77,1.31
135.4,2.26,0.08,40.83,1.32
135.6,2.26,0.08,40.84,1.32
135.8,2.26,0.08,40.94,1.32
136,2.27,0.08,41.05,1.32
136.2,2.27,0.08,41.05,1.32
136.4,2.27,0.08,41.16,1.33
136.6,2.28,0.08,41.22,1.33
136.8,2.28,0.08,41.32,1.33
137,2.28,0.08,41.35,1.33
137.2,2.29,0.08,41.35,1.33
137.4,2.29,0.08,41.47,1.34
137.6,2.29,0.08,41.55,1.34
137.8,2.3,0.09,41.64,1.34
138,2.3,0.09,41.67,1.34
138.2,2.3,0.09,41.72,1.34
138.4,2.31,0.09,41.77,1.34
138.6,2.31,0.09,41.92,1.35
138.8,2.31,0.09,41.96,1.35
139,2.32,0.09,42.02,1.35
139.2,2.32,0.09,42.05,1.35
139.4,2.32,0.09,42.12,1.35
139.6,2.33,0.09,42.19,1.36
139.8,2.33,0.09,42.28,1.36
140,2.33,0.09,42.34,1.36
140.2,2.34,0.09,42.42,1.36
140.4,2.34,0.09,42.47,1.36
140.6,2.34,0.09,42.54,1.37
140.8,2.35,0.09,42.59,1.37
141,2.35,0.09,42.62,1.37
141.2,2.35,0.09,42.74,1.37
141.4,2.36,0.09,42.81,1.37
141.6,2.36,0.09,42.9,1.38
141.8,2.36,0.09,42.97,1.38
142,2.37,0.09,43.01,1.38
142.2,2.37,0.09,43.09,1.38
142.4,2.37,0.09,43.13,1.38
142.6,2.38,0.09,43.18,1.39
142.8,2.38,0.09,43.25,1.39
143,2.38,0.09,43.32,1.39
143.2,2.39,0.09,43.42,1.39
143.4,2.39,0.09,43.43,1.39
143.6,2.39,0.09,43.56,1.4
143.8,2.4,0.09,43.57,1.4
144,2.4,0.09,43.65,1.4
144.2,2.4,0.09,43.74,1.4
144.4,2.41,0.09,43.83,1.4
144.6,2.41,0.09,43.81,1.4
144.8,2.41,0.09,43.92,1.41
145,2.42,0.09,43.96,1.41
145.2,2.42,0.09,44.06,1.41
145.4,2.42,0.09,44.12,1.41
145.6,2.43,0.09,44.21,1.41
145.8,2.43,0.09,44.29,1.42
146,2.43,0.09,44.28,1.42
146.2,2.44,0.09,44.36,1.42
146.4,2.44,0.09,44.45,1.42
146.6,2.44,0.09,44.51,1.42
146.8,2.45,0.09,44.54,1.43
147,2.45,0.09,44.68,1.43
147.2,2.45,0.09,44.71,1.43
147.4,2.46,0.09,44.76,1.43
147.6,2.46,0.09,44.84,1.43
147.8,2.46,0.09,44.9,1.44
148,2.47,0.09,44.98,1.44
148.2,2.47,0.09,45.07,1.44
148.4,2.47,0.09,45.12,1.44
148.6,2.48,0.09,45.17,1.44
148.8,2.48,0.09,45.27,1.45
149,2.48,0.09,45.31,1.45
149.2,2.49,0.09,45.34,1.45
149.4,2.49,0.09,45.44,1.45
149.6,2.49,0.09,45.5,1.45
149.8,2.5,0.09,45.6,1.46
150,2.5,0.09,45.64,1.46
150.2,2.5,0.09,45.71,1.46
150.4,2.51,0.09,45.81,1.46
150.6,2.51,0.09,45.83,1.46
150.8,2.51,0.09,45.87,1.47
151,2.52,0.09,45.97,1.47
151.2,2.52,0.09,46.03,1.47
151.4,2.52,0.09,46.03,1.47
151.6,2.53,0.09,46.21,1.47
151.8,2.53,0.09,46.2,1.47
152,2.53,0.09,46.29,1.48
152.2,2.54,0.09,46.33,1.48
152.4,2.54,0.09,46.42,1.48
152.6,2.54,0.09,46.53,1.48
152.8,2.55,0.1,46.56,1.48
153,2.55,0.1,46.65,1.49
153.2,2.55,0.1,46.74,1.49
153.4,2.56,0.1,46.81,1.49
153.6,2.56,0.1,46.82,1.49
153.8,2.56,0.1,46.93,1.49
154,2.57,0.1,47,1.5
154.2,2.57,0.1,47.11,1.5
154.4,2.57,0.1,47.11,1.5
154.6,2.58,0.1,47.17,1.5
154.8,2.58,0.1,47.27,1.5
155,2.58,0.1,47.29,1.51
155.2,2.59,0.1,47.42,1.51
155.4,2.59,0.1,47.46,1.51
155.6,2.59,0.1,47.52,1.51
155.8,2.6,0.1,47.57,1.51
156,2.6,0.1,47.65,1.52
156.2,2.6,0.1,47.68,1.52
156.4,2.61,0.1,47.8,1.52
156.6,2.61,0.1,47.93,1.52
156.8,2.61,0.1,47.93,1.52
157,2.62,0.1,47.99,1.53
157.2,2.62,0.1,48.05,1.53
157.4,2.62,0.1,48.08,1.53
157.6,2.63,0.1,48.17,1.53
157.8,2.63,0.1,48.25,1.53
158,2.63,0.1,48.29,1.54
158.2,2.64,0.1,48.45,1.54
158.4,2.64,0.1,48.41,1.54
158.6,2.64,0.1,48.57,1.54
158.8,2.65,0.1,48.61,1.54
159,2.65,0.1,48.65,1.54
159.2,2.65,0.1,48.71,1.55
159.4,2.66,0.1,48.81,1.55
159.6,2.66,0.1,48.85,1.55
159.8,2.66,0.1,48.86,1.55
160,2.67,0.1,48.97,1.55
160.2,2.67,0.1,49.02,1.56
160.4,2.67,0.1,49.11,1.56
160.6,2.68,0.1,49.18,1.56
160.8,2.68,0.1,49.19,1.56
161,2.68,0.1,49.3,1.56
161.2,2.69,0.1,49.4,1.57
161.4,2.69,0.1,49.41,1.57
161.6,2.69,0.1,49.53,1.57
161.8,2.7,0.1,49.57,1.57
162,2.7,0.1,49.61,1.57
162.2,2.7,0.1,49.71,1.58
162.4,2.71,0.1,49.82,1.58
162.6,2.71,0.1,49.87,1.58
162.8,2.71,0.1,49.94,1.58
163,2.72,0.1,50.02,1.58
163.2,2.72,0.1,50.02,1.59
163.4,2.72,0.1,50.17,1.59
163.6,2.73,0.1,50.17,1.59
163.8,2.73,0.1,50.24,1.59
164,2.73,0.1,50.32,1.59
164.2,2.74,0.1,50.36,1.6
164.4,2.74,0.1,50.44,1.6
164.6,2.74,0.1,50.52,1.6
164.8,2.75,0.1,50.59,1.6
165,2.75,0.1,50.65,1.6
165.2,2.75,0.1,50.74,1.61
165.4,2.76,0.1,50.76,1.61
165.6,2.76,0.1,50.84,1.61
165.8,2.76,0.1,50.92,1.61
166,2.77,0.1,50.96,1.61
166.2,2.77,0.1,51.03,1.61
166.4,2.77,0.1,51.09,1.62
166.6,2.78,0.1,51.13,1.62
166.8,2.78,0.1,51.25,1.62
167,2.78,0.1,51.35,1.62
167.2,2.79,0.1,51.37,1.62
167.4,2.79,0.11,51.43,1.63
167.6,2.79,0.11,51.52,1.63
167.8,2.8,0.11,51.56,1.63
168,2.8,0.11,51.61,1.63
168.2,2.8,0.11,51.68,1.63
168.4,2.81,0.11,51.73,1.64
168.6,2.81,0.11,51.79,1.64
168.8,2.81,0.11,51.86,1.64
169,2.82,0.11,52,1.64
169.2,2.82,0.11,51.99,1.64
169.4,2.82,0.11,52.09,1.65
169.6,2.83,0.11,52.14,1.65
169.8,2.83,0.11,52.19,1.65
170,2.83,0.11,52.25,1.65
170.2,2.84,0.11,52.3,1.65
170.4,2.84,0.11,52.41,1.66
170.6,2.84,0.11,52.46,1.66
170.8,2.85,0.11,52.53,1.66
171,2.85,0.11,52.69,1.66
171.2,2.85,0.11,52.64,1.66
171.4,2.86,0.11,52.71,1.67
171.6,2.86,0.11,52.79,1.67
171.8,2.86,0.11,52.84,1.67
172,2.87,0.11,52.93,1.67
172.2,2.87,0.11,52.96,1.67
172.4,2.87,0.11,53.03,1.68
172.6,2.88,0.11,53.13,1.68
172.8,2.88,0.11,53.14,1.68
173,2.88,0.11,53.22,1.68
173.2,2.89,0.11,53.37,1.68
173.4,2.89,0.11,53.36,1.69
173.6,2.89,0.11,53.43,1.69
173.8,2.9,0.11,53.5,1.69
174,2.9,0.11,53.52,1.69
174.2,2.9,0.11,53.62,1.69
174.4,2.91,0.11,53.74,1.69
174.6,2.91,0.11,53.77,1.7
174.8,2.91,0.11,53.83,1.7
175,2.92,0.11,53.88,1.7
175.2,2.92,0.11,53.96,1.7
175.4,2.92,0.11,54.01,1.7
175.6,2.93,0.11,54.1,1.71
175.8,2.93,0.11,54.14,1.71
176,2.93,0.11,54.21,1.71
176.2,2.94,0.11,54.27,1.71
176.4,2.94,0.11,54.35,1.71
176.6,2.94,0.11,54.39,1.72
176.8,2.95,0.11,54.45,1.72
177,2.95,0.11,54.53,1.72
177.2,2.95,0.11,54.6,1.72
177.4,2.96,0.11,54.64,1.72
177.6,2.96,0.11,54.71,1.73
177.8,2.96,0.11,54.76,1.73
178,2.97,0.11,54.79,1.73
178.2,2.97,0.11,54.97,1.73
178.4,2.97,0.11,55,1.73
178.6,2.98,0.11,55.02,1.74
178.8,2.98,0.11,55.12,1.74
179,2.98,0.11,55.22,1.74
179.2,2.99,0.11,55.24,1.74
179.4,2.99,0.11,55.28,1.74
179.6,2.99,0.11,55.41,1.75
179.8,3,0.11,55.4,1.75
180,3,0.11,55.49,1.75
180.2,3,0.11,55.59,1.75
180.4,3,0.11,55.66,1.75
180.6,3.01,0.11,55.71,1.76
180.8,3.01,0.11,55.78,1.76
181,3.02,0.11,55.84,1.76
181.2,3.02,0.11,55.88,1.76
181.4,3.02,0.11,55.93,1.76
181.6,3.03,0.11,56.02,1.76
181.8,3.03,0.11,56.05,1.77
182,3.03,0.11,56.17,1.77
182.2,3.04,0.11,56.2,1.77
182.4,3.04,0.11,56.31,1.77
182.6,3.04,0.12,56.35,1.77
182.8,3.05,0.12,56.36,1.78
183,3.05,0.12,56.51,1.78
183.2,3.05,0.12,56.53,1.78
183.4,3.06,0.12,56.59,1.78
183.6,3.06,0.12,56.68,1.78
183.8,3.06,0.12,56.72,1.79
184,3.07,0.12,56.81,1.79
184.2,3.07,0.12,56.89,1.79
184.4,3.07,0.12,56.95,1.79
184.6,3.08,0.12,56.98,1.79
184.8,3.08,0.12,57.03,1.8
185,3.08,0.12,57.12,1.8
185.2,3.08,0.12,57.2,1.8
185.4,3.09,0.12,57.19,1.8
185.6,3.09,0.12,57.27,1.8
185.8,3.1,0.12,57.37,1.81
186,3.1,-0.01,-6.46,1.81
186.2,3.1,-0.01,-4.27,1.81
186.4,3.11,-0.01,-4.22,1.81
186.6,3.11,-0.01,-4.25,1.81
186.8,3.11,-0.01,-4.21,1.82
187,3.12,-0.01,-4.27,1.82
187.2,3.12,-0.01,-4.27,1.82
187.4,3.12,-0.01,-4.31,1.82
187.6,3.13,-0.01,-4.23,1.82
187.8,3.13,-0.01,-4.22,1.83
188,3.13,-0.01,-4.24,1.83
188.2,3.14,-0.01,-4.23,1.83
188.4,3.14,-0.01,-4.17,1.83
188.6,3.14,-0.01,-4.27,1.83
188.8,3.15,-0.01,-4.24,1.83
189,3.15,-0.01,-4.21,1.84
189.2,3.15,-0.01,-4.22,1.84
189.4,3.16,-0.01,-4.19,1.84
189.6,3.16,-0.01,-4.22,1.84
189.8,3.16,-0.01,-4.21,1.84
190,3.17,-0.01,-4.22,1.85
190.2,3.17,-0.01,-4.23,1.85
190.4,3.17,-0.01,-4.26,1.85
190.6,3.18,-0.01,-4.25,1.85
190.8,3.18,-0.01,-4.2,1.85
191,3.18,-0.01,-4.22,1.86
191.2,3.19,-0.01,-4.24,1.86
191.4,3.19,-0.01,-4.23,1.86
191.6,3.19,-0.01,-4.23,1.86
191.8,3.2,-0.01,-4.18,1.86
192,3.2,-0.01,-4.24,1.87
192.2,3.2,-0.01,-4.22,1.87
192.4,3.21,-0.01,-4.23,1.87
192.6,3.21,-0.01,-4.28,1.87
192.8,3.21,-0.01,-4.23,1.87
193,3.22,-0.01,-4.25,1.88
193.2,3.22,-0.01,-4.21,1.88
193.4,3.22,-0.01,-4.25,1.88
193.6,3.23,-0.01,-4.2,1.88
193.8,3.23,-0.01,-4.21,1.88
194,3.23,-0.01,-4.23,1.89
194.2,3.24,-0.01,-4.2,1.89
194.4,3.24,-0.01,-4.2,1.89
194.6,3.24,-0.01,-4.15,1.89
194.8,3.25,-0.01,-4.18,1.89
195,3.25,-0.01,-4.21,1.89
195.2,3.25,-0.01,-4.21,1.9
195.4,3.26,-0.01,-4.19,1.9
195.6,3.26,-0.01,-4.24,1.9
195.8,3.26,-0.01,-4.22,1.9
196,3.27,-0.01,-4.2,1.9
196.2,3.27,-0.01,-4.22,1.91
196.4,3.27,-0.01,-4.23,1.91
196.6,3.28,-0.01,-4.2,1.91
196.8,3.28,-0.01,-4.21,1.91
197,3.28,-0.01,-4.2,1.91
197.2,3.29,-0.01,-4.18,1.92
197.4,3.29,-0.01,-4.28,1.92
197.6,3.29,-0.01,-4.18,1.92
197.8,3.3,-0.01,-4.26,1.92
198,3.3,-0.01,-4.23,1.92
198.2,3.3,-0.01,-4.21,1.93
198.4,3.31,-0.01,-4.22,1.93
198.6,3.31,-0.01,-4.23,1.93
198.8,3.31,-0.01,-4.24,1.93
199,3.32,-0.01,-4.23,1.93
199.2,3.32,-0.01,-4.24,1.94
199.4,3.32,-0.01,-4.21,1.94
199.6,3.33,-0.01,-4.22,1.94
199.8,3.33,-0.01,-4.22,1.94
200,3.33,-0.01,-4.21,1.94
200.2,3.34,-0.01,-4.23,1.95
200.4,3.34,-0.01,-4.19,1.95
200.6,3.34,-0.01,-4.21,1.95
200.8,3.35,-0.01,-4.24,1.95
201,3.35,-0.01,-4.17,1.95
201.2,3.35,-0.01,-4.18,1.96
201.4,3.36,-0.01,-4.2,1.96
201.6,3.36,-0.01,-4.21,1.96
201.8,3.36,-0.01,-4.23,1.96
202,3.37,-0.01,-4.23,1.96
202.2,3.37,-0.01,-4.21,1.97
202.4,3.37,-0.01,-4.21,1.97
202.6,3.38,-0.01,-4.21,1.97
202.8,3.38,-0.01,-4.25,1.97
203,3.38,-0.01,-4.21,1.97
203.2,3.39,-0.01,-4.23,1.97
203.4,3.39,-0.01,-4.21,1.98
203.6,3.39,-0.01,-4.22,1.98
203.8,3.4,-0.01,-4.17,1.98
204,3.4,-0.01,-4.22,1.98
204.2,3.4,-0.01,-4.26,1.98
204.4,3.41,-0.01,-4.23,1.99
204.6,3.41,-0.01,-4.23,1.99
204.8,3.41,-0.01,-4.21,1.99
205,3.42,-0.01,-4.25,1.99
205.2,3.42,-0.01,-4.19,1.99
205.4,3.42,-0.01,-4.24,2
205.6,3.43,-0.01,-4.26,2
205.8,3.43,-0.01,-4.16,2
206,3.43,-0.01,-4.18,2
206.2,3.44,-0.01,-4.24,2
206.4,3.44,-0.01,-4.2,2.01
206.6,3.44,-0.01,-4.23,2.01
206.8,3.45,-0.01,-4.19,2.01
207,3.45,-0.01,-4.22,2.01
207.2,3.45,-0.01,-4.24,2.01
207.4,3.46,-0.01,-4.17,2.02
207.6,3.46,-0.01,-4.18,2.02
207.8,3.46,-0.01,-4.23,2.02
207.86,3.46,-0.01,-4.21,2.02